<robot name="Pib">
<link name="base_link"></link>
<joint name="base_link_to_base" type="fixed">
<parent link="base_link"/>
<child link="urdf_body" />
<origin rpy="0.0 0 0" xyz="0 0 0"/>
</joint>
<link name="urdf_body">
<visual>
<origin xyz="0.41775263306263787921 -0.00066762609368168496227 1.0716467136047997943" rpy="0 -0 0" />
<geometry>
<mesh filename="package://pib_cal_sim/meshes/urdf_body.stl"/>
</geometry>
<material name="urdf_body_material">
<color rgba="0.90196078431372550543 0.90196078431372550543 0.90196078431372550543 1.0"/>
</material>
</visual>
<collision>
<origin xyz="0.41775263306263787921 -0.00066762609368168496227 1.0716467136047997943" rpy="0 -0 0" />
<geometry>
<mesh filename="package://pib_cal_sim/meshes/urdf_body.stl"/>
</geometry>
</collision>
<inertial>
<origin xyz="0.31489330912435326004 -0.012780142714819456642 0.62487202402964203696" rpy="0 0 0"/>
<mass value="13.849535511068582494" />
<inertia ixx="0.55078669867782281688" ixy="-1.9012914085606889641e-05"  ixz="0.001645294317393489799" iyy="0.61346106191160743037" iyz="0.002733187580724425348" izz="0.1047346160431014972" />
</inertial>
</link>

<link name="urdf_head_base">
<visual>
<origin xyz="0 -0.083390000000000005786 -0.046599999999999974776" rpy="3.141592653589793116 -0 0" />
<geometry>
<mesh filename="package://pib_cal_sim/meshes/urdf_head_base.stl"/>
</geometry>
<material name="urdf_head_base_material">
<color rgba="0.90196078431372550543 0.90196078431372550543 0.90196078431372550543 1.0"/>
</material>
</visual>
<collision>
<origin xyz="0 -0.083390000000000005786 -0.046599999999999974776" rpy="3.141592653589793116 -0 0" />
<geometry>
<mesh filename="package://pib_cal_sim/meshes/urdf_head_base.stl"/>
</geometry>
</collision>
<inertial>
<origin xyz="0.00084453312171220407643 0.0054549791054532698054 -0.015012590515738548358" rpy="0 0 0"/>
<mass value="0.1407332196056315099" />
<inertia ixx="6.8301393138811282196e-05" ixy="-3.5603263798047368922e-06"  ixz="-1.5702005793078214618e-08" iyy="0.00017143015354827780168" iyz="-8.7198135009501523636e-08" izz="0.00021767956241075907806" />
</inertial>
</link>

<link name="urdf_head">
<visual>
<origin xyz="0.13339000000000000856 0.031599999999999850431 0.055279999999999995808" rpy="-1.570796326794896558 -1.570796326794896558 0" />
<geometry>
<mesh filename="package://pib_cal_sim/meshes/urdf_head.stl"/>
</geometry>
<material name="urdf_head_material">
<color rgba="0.90196078431372550543 0.90196078431372550543 0.90196078431372550543 1.0"/>
</material>
</visual>
<collision>
<origin xyz="0.13339000000000000856 0.031599999999999850431 0.055279999999999995808" rpy="-1.570796326794896558 -1.570796326794896558 0" />
<geometry>
<mesh filename="package://pib_cal_sim/meshes/urdf_head.stl"/>
</geometry>
</collision>
<inertial>
<origin xyz="0.098817021835594237578 0.072010611053772530243 0.055527940061446935671" rpy="0 0 0"/>
<mass value="0.15000000000000043854" />
<inertia ixx="0.0010770836334109568783" ixy="-3.6887597283795509875e-05"  ixz="-4.5149123394523692896e-08" iyy="0.0011072239979683362859" iyz="2.8871692117175621428e-06" izz="0.00073482206415250805962" />
</inertial>
</link>

<link name="oak_d_lite">
<visual>
<origin xyz="-0.022000000000000005662 -0.0149999999999999023 0" rpy="1.570796326794896558 1.570796326794896336 0" />
<geometry>
<mesh filename="package://pib_cal_sim/meshes/oak_d_lite.stl"/>
</geometry>
<material name="oak_d_lite_material">
<color rgba="0.4000000000000000222 0.4000000000000000222 0.4000000000000000222 1.0"/>
</material>
</visual>
<collision>
<origin xyz="-0.022000000000000005662 -0.0149999999999999023 0" rpy="1.570796326794896558 1.570796326794896336 0" />
<geometry>
<mesh filename="package://pib_cal_sim/meshes/oak_d_lite.stl"/>
</geometry>
</collision>
<inertial>
<origin xyz="-0.0082557097676057029229 0.015883445555257832277 -0.0011312215300029637884" rpy="0 0 0"/>
<mass value="0.04899562972053378429" />
<inertia ixx="3.6507524523980586315e-05" ixy="3.0780221300466219909e-07"  ixz="-1.3595526115953150475e-07" iyy="3.234216192412520043e-05" iyz="1.3631479790165959179e-06" izz="6.2828563442396091553e-06" />
</inertial>
</link>

<link name="camera_link">
<visual>
<origin xyz="-0.1936976085799593239 -0.00049999999999994493294 -0.091483331406940524011" rpy="-1.570796326794896558 1.4888894576153667119e-64 0" />
<geometry>
<mesh filename="package://pib_cal_sim/meshes/camera_link.stl"/>
</geometry>
<material name="camera_link_material">
<color rgba="0.76862745098039220171 0.88627450980392152857 0.95294117647058818044 1.0"/>
</material>
</visual>
<collision>
<origin xyz="-0.1936976085799593239 -0.00049999999999994493294 -0.091483331406940524011" rpy="-1.570796326794896558 1.4888894576153667119e-64 0" />
<geometry>
<mesh filename="package://pib_cal_sim/meshes/camera_link.stl"/>
</geometry>
</collision>
<inertial>
<origin xyz="0 0 0" rpy="0 0 0"/>
<mass value="0" />
<inertia ixx="0" ixy="0"  ixz="0" iyy="0" iyz="0" izz="0" />
</inertial>
</link>

<joint name="camera_link" type="fixed">
<origin xyz="-0.0024109682588240033407 0.0089161029996609464376 5.0000049234277810228e-07" rpy="-3.141592653589793116 -1.570796326794896336 0" />
<parent link="oak_d_lite" />
<child link="camera_link" />
<axis xyz="0 0 1"/>
<limit effort="1" velocity="20" />
<joint_properties friction="0.0"/>
</joint>

<joint name="Oak-D_connector" type="fixed">
<origin xyz="0.1553900000000000281 0.016600000000000170175 0.055279999999999995808" rpy="3.141592653589793116 -4.9303806576309865964e-32 3.8412307484906466134e-47" />
<parent link="urdf_head" />
<child link="oak_d_lite" />
<axis xyz="0 0 1"/>
<limit effort="1" velocity="20" />
<joint_properties friction="0.0"/>
</joint>

<joint name="head_vertical" type="revolute">
<origin xyz="-0.055280000000001716653 0.050000000000004249379 -0.0149999999999999023" rpy="-1.570796326794896558 -0 -1.570796326794896558" />
<parent link="urdf_head_base" />
<child link="urdf_head" />
<axis xyz="0 0 1"/>
<limit effort="1" velocity="20" />
<joint_properties friction="0.0"/>
</joint>

<joint name="head_horizontal" type="revolute">
<origin xyz="0.31552263306263794718 -0.0040476260936843366789 1.2323967136047995208" rpy="3.141592653589793116 -0 3.141592653589793116" />
<parent link="urdf_body" />
<child link="urdf_head_base" />
<axis xyz="0 0 1"/>
<limit effort="1" velocity="20" />
<joint_properties friction="0.0"/>
</joint>

<link name="urdf_shoulder_horizontal">
<visual>
<origin xyz="0 -0.005588974447351513497 -0.0081999999999999850786" rpy="3.141592653589793116 -0 0" />
<geometry>
<mesh filename="package://pib_cal_sim/meshes/urdf_shoulder_horizontal.stl"/>
</geometry>
<material name="urdf_shoulder_horizontal_material">
<color rgba="0.90196078431372550543 0.90196078431372550543 0.90196078431372550543 1.0"/>
</material>
</visual>
<collision>
<origin xyz="0 -0.005588974447351513497 -0.0081999999999999850786" rpy="3.141592653589793116 -0 0" />
<geometry>
<mesh filename="package://pib_cal_sim/meshes/urdf_shoulder_horizontal.stl"/>
</geometry>
</collision>
<inertial>
<origin xyz="0.00014552549411057648333 -0.007582238974200652265 0.021127140613376407807" rpy="0 0 0"/>
<mass value="0.37235551761859836395" />
<inertia ixx="0.00069298290097298304198" ixy="-4.4552008487096244399e-07"  ixz="1.4458402066394956224e-06" iyy="0.00063232764424174547381" iyz="5.0607205205189875015e-05" izz="0.00072108918939828054069" />
</inertial>
</link>

<link name="urdf_shoulder_vertical_marker">
<visual>
<origin xyz="5.5511151231257827021e-17 -0.058199999999999807443 0.25000000000000005551" rpy="1.57079632679489678 1.570796326794896558 0" />
<geometry>
<mesh filename="package://pib_cal_sim/meshes/urdf_shoulder_vertical_marker.stl"/>
</geometry>
<material name="urdf_shoulder_vertical_marker_material">
<color rgba="0.90196078431372550543 0.90196078431372550543 0.90196078431372550543 1.0"/>
</material>
</visual>
<collision>
<origin xyz="5.5511151231257827021e-17 -0.058199999999999807443 0.25000000000000005551" rpy="1.57079632679489678 1.570796326794896558 0" />
<geometry>
<mesh filename="package://pib_cal_sim/meshes/urdf_shoulder_vertical_marker.stl"/>
</geometry>
</collision>
<inertial>
<origin xyz="0.011610090727555680626 0.048241922945604226447 -4.02080268191440382e-07" rpy="0 0 0"/>
<mass value="0.43436523068953353244" />
<inertia ixx="0.0011429070700469511762" ixy="1.8013711129626791709e-05"  ixz="-1.2502629346405238156e-08" iyy="0.00062863058911335242384" iyz="-6.168978924817860619e-09" izz="0.00081503450188824273347" />
</inertial>
</link>

<link name="urdf_ellbow_upper">
<visual>
<origin xyz="-6.9388939039072283776e-17 0 0.076337860000000090643" rpy="-3.141592653589793116 -1.0551802091847523698e-17 1.7634218473795275585e-17" />
<geometry>
<mesh filename="package://pib_cal_sim/meshes/urdf_ellbow_upper.stl"/>
</geometry>
<material name="urdf_ellbow_upper_material">
<color rgba="0.90196078431372550543 0.90196078431372550543 0.90196078431372550543 1.0"/>
</material>
</visual>
<collision>
<origin xyz="-6.9388939039072283776e-17 0 0.076337860000000090643" rpy="-3.141592653589793116 -1.0551802091847523698e-17 1.7634218473795275585e-17" />
<geometry>
<mesh filename="package://pib_cal_sim/meshes/urdf_ellbow_upper.stl"/>
</geometry>
</collision>
<inertial>
<origin xyz="-8.7828098901397027611e-05 0.0054300548508614734228 0.022553116578299184369" rpy="0 0 0"/>
<mass value="0.18102575322750719122" />
<inertia ixx="0.00016816998365107982795" ixy="-5.2718247233673514926e-07"  ixz="-2.0631507098791437276e-07" iyy="0.00028060174234195706241" iyz="-2.5081698616751802713e-05" izz="0.00027446559514037306791" />
</inertial>
</link>

<link name="urdf_ellbow_lower_marker">
<visual>
<origin xyz="0.021000000000000018652 0 0.25" rpy="1.570796326794896558 1.570796326794896558 0" />
<geometry>
<mesh filename="package://pib_cal_sim/meshes/urdf_ellbow_lower_marker.stl"/>
</geometry>
<material name="urdf_ellbow_lower_marker_material">
<color rgba="0.90196078431372550543 0.90196078431372550543 0.90196078431372550543 1.0"/>
</material>
</visual>
<collision>
<origin xyz="0.021000000000000018652 0 0.25" rpy="1.570796326794896558 1.570796326794896558 0" />
<geometry>
<mesh filename="package://pib_cal_sim/meshes/urdf_ellbow_lower_marker.stl"/>
</geometry>
</collision>
<inertial>
<origin xyz="0.020551972757338731607 0.040787447266183364525 0.001018196028607004644" rpy="0 0 0"/>
<mass value="0.20651670336625077562" />
<inertia ixx="0.00033802818975429347855" ixy="-3.8721614785863335084e-05"  ixz="8.9162623486336050791e-06" iyy="0.00034889299983257437846" iyz="3.4738558352071015525e-06" izz="0.00026833905193567720139" />
</inertial>
</link>

<link name="urdf_forearm_marker">
<visual>
<origin xyz="0.057963134702951085719 1.3877787807814456755e-17 0.14991149095678002467" rpy="3.141592653589793116 -0 -8.1578817092069625021e-17" />
<geometry>
<mesh filename="package://pib_cal_sim/meshes/urdf_forearm_marker.stl"/>
</geometry>
<material name="urdf_forearm_marker_material">
<color rgba="0.90196078431372550543 0.90196078431372550543 0.90196078431372550543 1.0"/>
</material>
</visual>
<collision>
<origin xyz="0.057963134702951085719 1.3877787807814456755e-17 0.14991149095678002467" rpy="3.141592653589793116 -0 -8.1578817092069625021e-17" />
<geometry>
<mesh filename="package://pib_cal_sim/meshes/urdf_forearm_marker.stl"/>
</geometry>
</collision>
<inertial>
<origin xyz="7.659534283818714151e-06 -0.0012073011042544401841 0.052068041606173343094" rpy="0 0 0"/>
<mass value="0.055999999999999952593" />
<inertia ixx="0.00016791550498575073293" ixy="-6.9647662101011056678e-10"  ixz="1.5058530731285986113e-08" iyy="0.00017557241384765504412" iyz="2.2983836036069200823e-06" izz="7.0754380195781182896e-05" />
</inertial>
</link>

<link name="urdf_palm_right">
<visual>
<origin xyz="0.0030000000000000720535 -0.099999999999999977796 -0.16769999999999998797" rpy="1.570796326794896558 1.5707963267948961139 0" />
<geometry>
<mesh filename="package://pib_cal_sim/meshes/urdf_palm_right.stl"/>
</geometry>
<material name="urdf_palm_right_material">
<color rgba="0.90196078431372550543 0.90196078431372550543 0.90196078431372550543 1.0"/>
</material>
</visual>
<collision>
<origin xyz="0.0030000000000000720535 -0.099999999999999977796 -0.16769999999999998797" rpy="1.570796326794896558 1.5707963267948961139 0" />
<geometry>
<mesh filename="package://pib_cal_sim/meshes/urdf_palm_right.stl"/>
</geometry>
</collision>
<inertial>
<origin xyz="0.001305973381060676489 -0.046625022672167074078 -0.027813878618658138819" rpy="0 0 0"/>
<mass value="0.17357112422069076452" />
<inertia ixx="0.00019637875852311336149" ixy="4.5633710391136445936e-06"  ixz="2.3520048803918759927e-06" iyy="7.681409307031837933e-05" iyz="7.8631919882522926824e-06" izz="0.00013864618298481778242" />
</inertial>
</link>

<link name="urdf_finger_proximal_marked">
<visual>
<origin xyz="0.050000000000000030531 -1.1102230246251565404e-16 0.050000000000000002776" rpy="1.570796326794896558 1.570796326794896558 0" />
<geometry>
<mesh filename="package://pib_cal_sim/meshes/urdf_finger_proximal_marked.stl"/>
</geometry>
<material name="urdf_finger_proximal_marked_material">
<color rgba="0.90196078431372550543 0.90196078431372550543 0.90196078431372550543 1.0"/>
</material>
</visual>
<collision>
<origin xyz="0.050000000000000030531 -1.1102230246251565404e-16 0.050000000000000002776" rpy="1.570796326794896558 1.570796326794896558 0" />
<geometry>
<mesh filename="package://pib_cal_sim/meshes/urdf_finger_proximal_marked.stl"/>
</geometry>
</collision>
<inertial>
<origin xyz="0.001744310342680524149 -0.024012285644793521927 2.3089936936983301852e-05" rpy="0 0 0"/>
<mass value="0.013455292396882858816" />
<inertia ixx="2.4193699728966932141e-06" ixy="2.2301674006392852555e-09"  ixz="-1.4015332326983234741e-09" iyy="7.0694386353011920957e-07" iyz="-5.2815456242914140059e-09" izz="2.3820803735124569276e-06" />
</inertial>
</link>

<link name="urdf_finger_distal_marked">
<visual>
<origin xyz="0.049999999999999988898 0.04799999999999993161 0.050000000000000002776" rpy="1.570796326794896558 1.570796326794896558 0" />
<geometry>
<mesh filename="package://pib_cal_sim/meshes/urdf_finger_distal_marked.stl"/>
</geometry>
<material name="urdf_finger_distal_marked_material">
<color rgba="0.90196078431372550543 0.90196078431372550543 0.90196078431372550543 1.0"/>
</material>
</visual>
<collision>
<origin xyz="0.049999999999999988898 0.04799999999999993161 0.050000000000000002776" rpy="1.570796326794896558 1.570796326794896558 0" />
<geometry>
<mesh filename="package://pib_cal_sim/meshes/urdf_finger_distal_marked.stl"/>
</geometry>
</collision>
<inertial>
<origin xyz="0.0040307381601225487563 -0.025106478373595697562 8.7643060661668492628e-06" rpy="0 0 0"/>
<mass value="0.015938305667451857506" />
<inertia ixx="2.8966795776703682079e-06" ixy="4.022318067867839793e-07"  ixz="5.5443573735113198068e-10" iyy="9.5458226992992813171e-07" iyz="-1.2982138146621890987e-09" izz="2.8682097363609259013e-06" />
</inertial>
</link>

<link name="sticker_purple">
<visual>
<origin xyz="0.041831607790372760114 -0.042995058148414880272 -0.0001999999999999502176" rpy="0 2.7755575615628907348e-17 6.9388939039072268369e-18" />
<geometry>
<mesh filename="package://pib_cal_sim/meshes/sticker_purple.stl"/>
</geometry>
<material name="sticker_purple_material">
<color rgba="0.59607843137254901134 0.12156862745098039047 0.6745098039215686736 1.0"/>
</material>
</visual>
<collision>
<origin xyz="0.041831607790372760114 -0.042995058148414880272 -0.0001999999999999502176" rpy="0 2.7755575615628907348e-17 6.9388939039072268369e-18" />
<geometry>
<mesh filename="package://pib_cal_sim/meshes/sticker_purple.stl"/>
</geometry>
</collision>
<inertial>
<origin xyz="-3.4694469519536141888e-17 -4.886217547094266053e-17 -9.9999999999949060843e-05" rpy="0 0 0"/>
<mass value="1.3079078535425004304e-05" />
<inertia ixx="5.2359911070151372804e-11" ixy="3.6331986773379787353e-28"  ixz="-1.4532794709351914941e-27" iyy="5.2359911070151327568e-11" iyz="3.630173532727370159e-28" izz="1.0463262828339980348e-10" />
</inertial>
</link>

<joint name="connector_purple1" type="fixed">
<origin xyz="0.013963400712812490401 -0.029452939894911600582 -6.9388939039072283776e-18" rpy="-1.5707963267948961139 1.3877787807814543037e-17 -1.3633001010513503548" />
<parent link="urdf_finger_distal_marked" />
<child link="sticker_purple" />
<axis xyz="0 0 1"/>
<limit effort="1" velocity="20" />
<joint_properties friction="0.0"/>
</joint>

<joint name="pinky_right_distal" type="revolute">
<origin xyz="-1.3877787807814456755e-17 -0.048000000000000153655 2.4286128663675299322e-17" rpy="-5.1000870193717868252e-15 -2.319708381060618237e-15 3.2847701601687899034e-16" />
<parent link="urdf_finger_proximal_marked" />
<child link="urdf_finger_distal_marked" />
<axis xyz="0 0 1"/>
<limit effort="1" velocity="20" />
<joint_properties friction="0.0"/>
</joint>

<link name="sticker_purple_2">
<visual>
<origin xyz="0.041831607790372760114 0.042995058148414824761 1.3877787807814456755e-17" rpy="3.141592653589793116 -1.1592614399203713543e-18 6.9388939039072299184e-18" />
<geometry>
<mesh filename="package://pib_cal_sim/meshes/sticker_purple.stl"/>
</geometry>
<material name="sticker_purple_material">
<color rgba="0.59607843137254901134 0.12156862745098039047 0.6745098039215686736 1.0"/>
</material>
</visual>
<collision>
<origin xyz="0.041831607790372760114 0.042995058148414824761 1.3877787807814456755e-17" rpy="3.141592653589793116 -1.1592614399203713543e-18 6.9388939039072299184e-18" />
<geometry>
<mesh filename="package://pib_cal_sim/meshes/sticker_purple.stl"/>
</geometry>
</collision>
<inertial>
<origin xyz="-2.0816681711721685133e-17 -7.22790938695971654e-18 -9.9999999999985476483e-05" rpy="0 0 0"/>
<mass value="1.3079078535425004304e-05" />
<inertia ixx="5.235991107015133403e-11" ixy="7.2663973546759538833e-28"  ixz="6.8702315973423964021e-28" iyy="5.2359911070151327568e-11" iyz="-2.1703501833316977378e-27" izz="1.0463262828339982933e-10" />
</inertial>
</link>

<joint name="connector_purple2" type="fixed">
<origin xyz="0.01254051999999997169 -0.018571890849898409215 1.0408340855860842566e-17" rpy="1.5707963267948970021 -9.0205620750794523577e-17 1.570796326794896558" />
<parent link="urdf_finger_proximal_marked" />
<child link="sticker_purple_2" />
<axis xyz="0 0 1"/>
<limit effort="1" velocity="20" />
<joint_properties friction="0.0"/>
</joint>

<joint name="pinky_right_proximal" type="revolute">
<origin xyz="0.0030000000000000304201 -0.075546139999999817327 -0.065820549999999977686" rpy="0.31415926535898203165 -2.3357961940195453957e-15 5.9003337578891788935e-15" />
<parent link="urdf_palm_right" />
<child link="urdf_finger_proximal_marked" />
<axis xyz="0 0 1"/>
<limit effort="1" velocity="20" />
<joint_properties friction="0.0"/>
</joint>

<link name="urdf_finger_proximal_marked_2">
<visual>
<origin xyz="0.050000000000000002776 0 0.050000000000000016653" rpy="1.570796326794896558 1.570796326794896336 0" />
<geometry>
<mesh filename="package://pib_cal_sim/meshes/urdf_finger_proximal_marked.stl"/>
</geometry>
<material name="urdf_finger_proximal_marked_material">
<color rgba="0.90196078431372550543 0.90196078431372550543 0.90196078431372550543 1.0"/>
</material>
</visual>
<collision>
<origin xyz="0.050000000000000002776 0 0.050000000000000016653" rpy="1.570796326794896558 1.570796326794896336 0" />
<geometry>
<mesh filename="package://pib_cal_sim/meshes/urdf_finger_proximal_marked.stl"/>
</geometry>
</collision>
<inertial>
<origin xyz="0.0017443103426804907555 -0.024012285644793414374 2.308993693699717964e-05" rpy="0 0 0"/>
<mass value="0.013455292396882858816" />
<inertia ixx="2.4193699728966932141e-06" ixy="2.2301674006392773973e-09"  ixz="-1.4015332326981603127e-09" iyy="7.0694386353011942133e-07" iyz="-5.2815456242914214505e-09" izz="2.3820803735124569276e-06" />
</inertial>
</link>

<link name="urdf_finger_distal_marked_2">
<visual>
<origin xyz="0.049999999999999988898 0.048000000000000042633 0.050000000000000002776" rpy="1.570796326794896558 1.570796326794896558 0" />
<geometry>
<mesh filename="package://pib_cal_sim/meshes/urdf_finger_distal_marked.stl"/>
</geometry>
<material name="urdf_finger_distal_marked_material">
<color rgba="0.90196078431372550543 0.90196078431372550543 0.90196078431372550543 1.0"/>
</material>
</visual>
<collision>
<origin xyz="0.049999999999999988898 0.048000000000000042633 0.050000000000000002776" rpy="1.570796326794896558 1.570796326794896558 0" />
<geometry>
<mesh filename="package://pib_cal_sim/meshes/urdf_finger_distal_marked.stl"/>
</geometry>
</collision>
<inertial>
<origin xyz="0.0040307381601225556952 -0.025106478373595600417 8.7643060661668492628e-06" rpy="0 0 0"/>
<mass value="0.015938305667451857506" />
<inertia ixx="2.8966795776703673609e-06" ixy="4.0223180678678403224e-07"  ixz="5.5443573735106239411e-10" iyy="9.5458226992992855523e-07" iyz="-1.2982138146622221859e-09" izz="2.8682097363609259013e-06" />
</inertial>
</link>

<link name="sticker_blue">
<visual>
<origin xyz="0.056831607790372717925 -0.057995058148414824206 -0.00019999999999997797318" rpy="6.9388939039072296102e-17 -0 -1.3877787807814456755e-17" />
<geometry>
<mesh filename="package://pib_cal_sim/meshes/sticker_blue.stl"/>
</geometry>
<material name="sticker_blue_material">
<color rgba="0 0 1 1.0"/>
</material>
</visual>
<collision>
<origin xyz="0.056831607790372717925 -0.057995058148414824206 -0.00019999999999997797318" rpy="6.9388939039072296102e-17 -0 -1.3877787807814456755e-17" />
<geometry>
<mesh filename="package://pib_cal_sim/meshes/sticker_blue.stl"/>
</geometry>
</collision>
<inertial>
<origin xyz="-6.9388939039072283776e-17 2.1599480645595093783e-17 -9.999999999997398394e-05" rpy="0 0 0"/>
<mass value="1.3079078535425004304e-05" />
<inertia ixx="5.2359911070151346955e-11" ixy="-7.2663973546759538833e-28"  ixz="-2.9041388261818961272e-27" iyy="5.2359911070151353417e-11" iyz="-2.5380963282985522838e-27" izz="1.0463262828339980348e-10" />
</inertial>
</link>

<joint name="connector_blue1" type="fixed">
<origin xyz="0.013963400712812462645 -0.029452939894911656094 -2.7755575615628913511e-17" rpy="-1.570796326794896336 1.3877787807814469081e-17 -1.363300101051331481" />
<parent link="urdf_finger_distal_marked_2" />
<child link="sticker_blue" />
<axis xyz="0 0 1"/>
<limit effort="1" velocity="20" />
<joint_properties friction="0.0"/>
</joint>

<joint name="ring_right_distal" type="revolute">
<origin xyz="2.7755575615628913511e-17 -0.047999999999999987121 0" rpy="-5.453970608471199834e-15 7.1019882218085448614e-16 7.0535592090159399233e-16" />
<parent link="urdf_finger_proximal_marked_2" />
<child link="urdf_finger_distal_marked_2" />
<axis xyz="0 0 1"/>
<limit effort="1" velocity="20" />
<joint_properties friction="0.0"/>
</joint>

<link name="sticker_blue_2">
<visual>
<origin xyz="0.056831607790372773437 0.057995058148414851962 1.3877787807814456755e-17" rpy="-3.141592653589793116 -3.202188788462029989e-18 0" />
<geometry>
<mesh filename="package://pib_cal_sim/meshes/sticker_blue.stl"/>
</geometry>
<material name="sticker_blue_material">
<color rgba="0 0 1 1.0"/>
</material>
</visual>
<collision>
<origin xyz="0.056831607790372773437 0.057995058148414851962 1.3877787807814456755e-17" rpy="-3.141592653589793116 -3.202188788462029989e-18 0" />
<geometry>
<mesh filename="package://pib_cal_sim/meshes/sticker_blue.stl"/>
</geometry>
</collision>
<inertial>
<origin xyz="-2.7755575615628913511e-17 6.9317972729432010652e-18 -9.9999999999986885946e-05" rpy="0 0 0"/>
<mass value="1.3079078535425004304e-05" />
<inertia ixx="5.2359911070151372804e-11" ixy="-7.2663973546759556769e-28"  ixz="-1.4180598760728817423e-27" iyy="5.2359911070151353417e-11" iyz="7.9372790217119269231e-27" izz="1.0463262828339982933e-10" />
</inertial>
</link>

<joint name="connector_blue2" type="fixed">
<origin xyz="0.012540519999999957812 -0.018571890849898520237 -2.7755575615628913511e-17" rpy="1.5707963267948961139 -2.7755575615628932e-17 1.5707963267948970021" />
<parent link="urdf_finger_proximal_marked_2" />
<child link="sticker_blue_2" />
<axis xyz="0 0 1"/>
<limit effort="1" velocity="20" />
<joint_properties friction="0.0"/>
</joint>

<joint name="ring_right_proximal" type="revolute">
<origin xyz="0.0030000000000000165423 -0.088617510000000065951 -0.043501980000000023407" rpy="0.17453292519943028327 1.2331238028113061221e-15 3.0395984963138164841e-15" />
<parent link="urdf_palm_right" />
<child link="urdf_finger_proximal_marked_2" />
<axis xyz="0 0 1"/>
<limit effort="1" velocity="20" />
<joint_properties friction="0.0"/>
</joint>

<link name="urdf_finger_proximal_marked_3">
<visual>
<origin xyz="0.049999999999999933387 0 0.049999999999999961142" rpy="1.570796326794896558 1.570796326794896558 0" />
<geometry>
<mesh filename="package://pib_cal_sim/meshes/urdf_finger_proximal_marked.stl"/>
</geometry>
<material name="urdf_finger_proximal_marked_material">
<color rgba="0.90196078431372550543 0.90196078431372550543 0.90196078431372550543 1.0"/>
</material>
</visual>
<collision>
<origin xyz="0.049999999999999933387 0 0.049999999999999961142" rpy="1.570796326794896558 1.570796326794896558 0" />
<geometry>
<mesh filename="package://pib_cal_sim/meshes/urdf_finger_proximal_marked.stl"/>
</geometry>
</collision>
<inertial>
<origin xyz="0.0017443103426804445685 -0.024012285644793414374 2.308993693694861077e-05" rpy="0 0 0"/>
<mass value="0.013455292396882858816" />
<inertia ixx="2.4193699728966923671e-06" ixy="2.2301674006392902186e-09"  ixz="-1.4015332326989668138e-09" iyy="7.0694386353011942133e-07" iyz="-5.2815456242913974623e-09" izz="2.3820803735124560806e-06" />
</inertial>
</link>

<link name="urdf_finger_distal_marked_3">
<visual>
<origin xyz="0.049999999999999988898 0.04799999999999993161 0.049999999999999961142" rpy="1.570796326794896558 1.570796326794896558 0" />
<geometry>
<mesh filename="package://pib_cal_sim/meshes/urdf_finger_distal_marked.stl"/>
</geometry>
<material name="urdf_finger_distal_marked_material">
<color rgba="0.90196078431372550543 0.90196078431372550543 0.90196078431372550543 1.0"/>
</material>
</visual>
<collision>
<origin xyz="0.049999999999999988898 0.04799999999999993161 0.049999999999999961142" rpy="1.570796326794896558 1.570796326794896558 0" />
<geometry>
<mesh filename="package://pib_cal_sim/meshes/urdf_finger_distal_marked.stl"/>
</geometry>
</collision>
<inertial>
<origin xyz="0.0040307381601225626341 -0.02510647837359571144 8.7643060661252158994e-06" rpy="0 0 0"/>
<mass value="0.015938305667451857506" />
<inertia ixx="2.8966795776703682079e-06" ixy="4.0223180678678403224e-07"  ixz="5.5443573735057373717e-10" iyy="9.5458226992992855523e-07" iyz="-1.2982138146621909599e-09" izz="2.8682097363609259013e-06" />
</inertial>
</link>

<link name="sticker_green">
<visual>
<origin xyz="0.041831607790372760114 0.057995058148414879717 2.7755575615628913511e-17" rpy="3.141592653589793116 5.5511151231257827021e-17 -2.7755575615628913511e-17" />
<geometry>
<mesh filename="package://pib_cal_sim/meshes/sticker_green.stl"/>
</geometry>
<material name="sticker_green_material">
<color rgba="0.37254901960784314596 0.65490196078431373028 0.23921568627450981448 1.0"/>
</material>
</visual>
<collision>
<origin xyz="0.041831607790372760114 0.057995058148414879717 2.7755575615628913511e-17" rpy="3.141592653589793116 5.5511151231257827021e-17 -2.7755575615628913511e-17" />
<geometry>
<mesh filename="package://pib_cal_sim/meshes/sticker_green.stl"/>
</geometry>
</collision>
<inertial>
<origin xyz="-2.7755575615628913511e-17 5.6666660469283727607e-17 -9.9999999999969145688e-05" rpy="0 0 0"/>
<mass value="1.3079078535425004304e-05" />
<inertia ixx="5.2359911070151340492e-11" ixy="1.4532794709351897005e-27"  ixz="-5.8106977680522780392e-27" iyy="5.2359911070151314643e-11" iyz="5.0816379168961981216e-27" izz="1.0463262828339982933e-10" />
</inertial>
</link>

<joint name="connector_green1" type="fixed">
<origin xyz="0.013963400712812462645 -0.029452939894911545071 0" rpy="-1.5707963267948961139 2.4980018054066096115e-16 -1.363300101051331481" />
<parent link="urdf_finger_distal_marked_3" />
<child link="sticker_green" />
<axis xyz="0 0 1"/>
<limit effort="1" velocity="20" />
<joint_properties friction="0.0"/>
</joint>

<joint name="middle_right_distal" type="revolute">
<origin xyz="-4.1633363423443370266e-17 -0.04799999999999993161 0" rpy="7.5495165674511985812e-15 -5.7736161153334870425e-15 -9.0423124955902406633e-18" />
<parent link="urdf_finger_proximal_marked_3" />
<child link="urdf_finger_distal_marked_3" />
<axis xyz="0 0 1"/>
<limit effort="1" velocity="20" />
<joint_properties friction="0.0"/>
</joint>

<link name="sticker_green_2">
<visual>
<origin xyz="0.041831607790372760114 0.057995058148414796451 1.3877787807814456755e-17" rpy="-3.141592653589793116 9.7753770057230056583e-18 0" />
<geometry>
<mesh filename="package://pib_cal_sim/meshes/sticker_green.stl"/>
</geometry>
<material name="sticker_green_material">
<color rgba="0.37254901960784314596 0.65490196078431373028 0.23921568627450981448 1.0"/>
</material>
</visual>
<collision>
<origin xyz="0.041831607790372760114 0.057995058148414796451 1.3877787807814456755e-17" rpy="-3.141592653589793116 9.7753770057230056583e-18 0" />
<geometry>
<mesh filename="package://pib_cal_sim/meshes/sticker_green.stl"/>
</geometry>
</collision>
<inertial>
<origin xyz="-2.7755575615628913511e-17 -3.4693117637124513224e-17 -9.9999999999987563572e-05" rpy="0 0 0"/>
<mass value="1.3079078535425004304e-05" />
<inertia ixx="5.2359911070151340492e-11" ixy="-3.9672053770570591994e-44"  ixz="2.4227408640581334188e-27" iyy="5.2359911070151327568e-11" iyz="2.5357123711787728545e-28" izz="1.0463262828339982933e-10" />
</inertial>
</link>

<joint name="connector_green2" type="fixed">
<origin xyz="0.012540519999999943934 -0.018571890849898464726 2.7755575615628913511e-17" rpy="1.5707963267948961139 -1.1102230246251565404e-16 1.5707963267948961139" />
<parent link="urdf_finger_proximal_marked_3" />
<child link="sticker_green_2" />
<axis xyz="0 0 1"/>
<limit effort="1" velocity="20" />
<joint_properties friction="0.0"/>
</joint>

<joint name="middle_right_proximal" type="revolute">
<origin xyz="0.002999999999999974909 -0.099999999999999866773 -0.017699999999999993516" rpy="-8.1046280797637358307e-15 3.9360729668295620438e-15 -8.585948255718946071e-16" />
<parent link="urdf_palm_right" />
<child link="urdf_finger_proximal_marked_3" />
<axis xyz="0 0 1"/>
<limit effort="1" velocity="20" />
<joint_properties friction="0.0"/>
</joint>

<link name="urdf_finger_proximal_marked_4">
<visual>
<origin xyz="0.050000000000000002776 5.5511151231257827021e-17 0.050000000000000044409" rpy="1.570796326794896558 1.570796326794896336 0" />
<geometry>
<mesh filename="package://pib_cal_sim/meshes/urdf_finger_proximal_marked.stl"/>
</geometry>
<material name="urdf_finger_proximal_marked_material">
<color rgba="0.90196078431372550543 0.90196078431372550543 0.90196078431372550543 1.0"/>
</material>
</visual>
<collision>
<origin xyz="0.050000000000000002776 5.5511151231257827021e-17 0.050000000000000044409" rpy="1.570796326794896558 1.570796326794896336 0" />
<geometry>
<mesh filename="package://pib_cal_sim/meshes/urdf_finger_proximal_marked.stl"/>
</geometry>
</collision>
<inertial>
<origin xyz="0.0017443103426804916229 -0.024012285644793351924 2.3089936937024935215e-05" rpy="0 0 0"/>
<mass value="0.013455292396882858816" />
<inertia ixx="2.4193699728966932141e-06" ixy="2.2301674006393191699e-09"  ixz="-1.4015332326983540798e-09" iyy="7.0694386353011942133e-07" iyz="-5.2815456242916232826e-09" izz="2.3820803735124569276e-06" />
</inertial>
</link>

<link name="urdf_finger_distal_marked_4">
<visual>
<origin xyz="0.049999999999999988898 0.047999999999999876099 0.049999999999999933387" rpy="1.57079632679489678 1.570796326794896558 0" />
<geometry>
<mesh filename="package://pib_cal_sim/meshes/urdf_finger_distal_marked.stl"/>
</geometry>
<material name="urdf_finger_distal_marked_material">
<color rgba="0.90196078431372550543 0.90196078431372550543 0.90196078431372550543 1.0"/>
</material>
</visual>
<collision>
<origin xyz="0.049999999999999988898 0.047999999999999876099 0.049999999999999933387" rpy="1.57079632679489678 1.570796326794896558 0" />
<geometry>
<mesh filename="package://pib_cal_sim/meshes/urdf_finger_distal_marked.stl"/>
</geometry>
</collision>
<inertial>
<origin xyz="0.00403073816012255743 -0.025106478373595753073 8.7643060660974603238e-06" rpy="0 0 0"/>
<mass value="0.015938305667451857506" />
<inertia ixx="2.8966795776703682079e-06" ixy="4.0223180678678382048e-07"  ixz="5.5443573735072128551e-10" iyy="9.5458226992992813171e-07" iyz="-1.2982138146621779318e-09" izz="2.8682097363609259013e-06" />
</inertial>
</link>

<link name="sticker_red">
<visual>
<origin xyz="0.056831607790372773437 -0.042995058148414921906 -0.00019999999999997797318" rpy="-1.3877787807814456755e-17 -0 5.5511151231257827021e-17" />
<geometry>
<mesh filename="package://pib_cal_sim/meshes/sticker_red.stl"/>
</geometry>
<material name="sticker_red_material">
<color rgba="1 0 0 1.0"/>
</material>
</visual>
<collision>
<origin xyz="0.056831607790372773437 -0.042995058148414921906 -0.00019999999999997797318" rpy="-1.3877787807814456755e-17 -0 5.5511151231257827021e-17" />
<geometry>
<mesh filename="package://pib_cal_sim/meshes/sticker_red.stl"/>
</geometry>
</collision>
<inertial>
<origin xyz="-1.3877787807814456755e-17 -9.3364572061903229366e-17 -9.9999999999978564694e-05" rpy="0 0 0"/>
<mass value="1.3079078535425004304e-05" />
<inertia ixx="5.2359911070151346955e-11" ixy="5.8131178837407631066e-27"  ixz="-4.0336608246182864481e-44" iyy="5.2359911070151327568e-11" iyz="-5.0828479747404399378e-27" izz="1.0463262828339982933e-10" />
</inertial>
</link>

<joint name="connector_red1" type="fixed">
<origin xyz="0.013963400712812504278 -0.029452939894911600582 0" rpy="-1.5707963267948961139 -0 -1.3633001010513370321" />
<parent link="urdf_finger_distal_marked_4" />
<child link="sticker_red" />
<axis xyz="0 0 1"/>
<limit effort="1" velocity="20" />
<joint_properties friction="0.0"/>
</joint>

<joint name="index_right_distal" type="revolute">
<origin xyz="6.9388939039072283776e-17 -0.047999999999999987121 5.5511151231257827021e-17" rpy="-9.9920072216266159398e-16 -3.1008280553197859637e-16 3.1645875993458667287e-15" />
<parent link="urdf_finger_proximal_marked_4" />
<child link="urdf_finger_distal_marked_4" />
<axis xyz="0 0 1"/>
<limit effort="1" velocity="20" />
<joint_properties friction="0.0"/>
</joint>

<link name="sticker_red_2">
<visual>
<origin xyz="0.056831607790372884459 0.042995058148414866395 1.3877787807814456755e-17" rpy="3.141592653589793116 -1.0473307373869963321e-17 -5.5511151231257827021e-17" />
<geometry>
<mesh filename="package://pib_cal_sim/meshes/sticker_red.stl"/>
</geometry>
<material name="sticker_red_material">
<color rgba="1 0 0 1.0"/>
</material>
</visual>
<collision>
<origin xyz="0.056831607790372884459 0.042995058148414866395 1.3877787807814456755e-17" rpy="3.141592653589793116 -1.0473307373869963321e-17 -5.5511151231257827021e-17" />
<geometry>
<mesh filename="package://pib_cal_sim/meshes/sticker_red.stl"/>
</geometry>
</collision>
<inertial>
<origin xyz="9.7144514654701197287e-17 3.7846715051986643392e-17 -9.9999999999984703989e-05" rpy="0 0 0"/>
<mass value="1.3079078535425004304e-05" />
<inertia ixx="5.2359911070151346955e-11" ixy="-1.268302666461214326e-42"  ixz="-7.0075597332094826188e-27" iyy="5.2359911070151327568e-11" iyz="1.9339557065293096017e-28" izz="1.0463262828339982933e-10" />
</inertial>
</link>

<joint name="connector_red2" type="fixed">
<origin xyz="0.012540520000000041079 -0.018571890849898575748 0" rpy="1.5707963267948961139 5.5511151231257716088e-17 1.5707963267949121011" />
<parent link="urdf_finger_proximal_marked_4" />
<child link="sticker_red_2" />
<axis xyz="0 0 1"/>
<limit effort="1" velocity="20" />
<joint_properties friction="0.0"/>
</joint>

<joint name="index_right_proximal" type="revolute">
<origin xyz="0.0029999999999999610312 -0.088617510000000065951 0.0081019800000000086193" rpy="-0.17453292519942251171 1.2132929916874613294e-15 -4.9273947210861152528e-15" />
<parent link="urdf_palm_right" />
<child link="urdf_finger_proximal_marked_4" />
<axis xyz="0 0 1"/>
<limit effort="1" velocity="20" />
<joint_properties friction="0.0"/>
</joint>

<link name="urdf_thumb_rotator_right">
<visual>
<origin xyz="0.17636699801262439857 0.0068405200000000165872 -0.0067226535902303874437" rpy="-3.141592653589793116 -0.20943951023931928201 2.1047903654459104234e-19" />
<geometry>
<mesh filename="package://pib_cal_sim/meshes/urdf_thumb_rotator_right.stl"/>
</geometry>
<material name="urdf_thumb_rotator_right_material">
<color rgba="0.90196078431372550543 0.90196078431372550543 0.90196078431372550543 1.0"/>
</material>
</visual>
<collision>
<origin xyz="0.17636699801262439857 0.0068405200000000165872 -0.0067226535902303874437" rpy="-3.141592653589793116 -0.20943951023931928201 2.1047903654459104234e-19" />
<geometry>
<mesh filename="package://pib_cal_sim/meshes/urdf_thumb_rotator_right.stl"/>
</geometry>
</collision>
<inertial>
<origin xyz="-0.0029395879088345844288 0.0010223868004371199254 0.025610109828915185448" rpy="0 0 0"/>
<mass value="0.016859773057134867791" />
<inertia ixx="2.0741870116576211107e-06" ixy="1.3174248602183413252e-07"  ixz="2.7719044306966139395e-07" iyy="2.4923475307751140139e-06" iyz="-4.4100052809894980775e-08" izz="1.6322356151522197996e-06" />
</inertial>
</link>

<link name="urdf_finger_proximal">
<visual>
<origin xyz="-5.5511151231257827021e-17 5.5511151231257827021e-17 0" rpy="1.570796326794896558 1.570796326794896558 0" />
<geometry>
<mesh filename="package://pib_cal_sim/meshes/urdf_finger_proximal.stl"/>
</geometry>
<material name="urdf_finger_proximal_material">
<color rgba="0.90196078431372550543 0.90196078431372550543 0.90196078431372550543 1.0"/>
</material>
</visual>
<collision>
<origin xyz="-5.5511151231257827021e-17 5.5511151231257827021e-17 0" rpy="1.570796326794896558 1.570796326794896558 0" />
<geometry>
<mesh filename="package://pib_cal_sim/meshes/urdf_finger_proximal.stl"/>
</geometry>
</collision>
<inertial>
<origin xyz="0.0017705852400310233535 -0.023999099540417907772 2.3033977339243577126e-05" rpy="0 0 0"/>
<mass value="0.013487983354878252049" />
<inertia ixx="2.4205995838425492106e-06" ixy="3.0678428291191867735e-10"  ixz="-1.3933704801256927674e-09" iyy="7.1089856531410673884e-07" iyz="-5.2774001918341160646e-09" izz="2.3870217482857900654e-06" />
</inertial>
</link>

<link name="urdf_finger_distal">
<visual>
<origin xyz="0 -0.048000000000000042633 0" rpy="-1.570796326794896558 -1.570796326794896558 0" />
<geometry>
<mesh filename="package://pib_cal_sim/meshes/urdf_finger_distal.stl"/>
</geometry>
<material name="urdf_finger_distal_material">
<color rgba="0.90196078431372550543 0.90196078431372550543 0.90196078431372550543 1.0"/>
</material>
</visual>
<collision>
<origin xyz="0 -0.048000000000000042633 0" rpy="-1.570796326794896558 -1.570796326794896558 0" />
<geometry>
<mesh filename="package://pib_cal_sim/meshes/urdf_finger_distal.stl"/>
</geometry>
</collision>
<inertial>
<origin xyz="0.0040511578091626697026 0.025115354711068141325 -8.7468318803049846652e-06" rpy="0 0 0"/>
<mass value="0.015970996140918996414" />
<inertia ixx="2.8975511698245469831e-06" ixy="-4.0367178625229541496e-07"  ixz="-5.5725852893885017627e-10" iyy="9.5795739134608061105e-07" iyz="-1.2993500709769918796e-09" izz="2.8722130952212174432e-06" />
</inertial>
</link>

<joint name="thumb_right_distal" type="revolute">
<origin xyz="-2.2204460492503130808e-16 -0.047999999999999987121 5.5511151231257827021e-17" rpy="-3.1415926535897868987 -9.9920072216264778891e-16 0" />
<parent link="urdf_finger_proximal" />
<child link="urdf_finger_distal" />
<axis xyz="0 0 1"/>
<limit effort="1" velocity="20" />
<joint_properties friction="0.0"/>
</joint>

<joint name="thumb_right_proximal" type="revolute">
<origin xyz="-0.020000000000000017764 0.0013202599999999897751 0.029914960629476239351" rpy="-2.4424906541753626905e-14 1.0471975511966016281 -1.5707963267949160979" />
<parent link="urdf_thumb_rotator_right" />
<child link="urdf_finger_proximal" />
<axis xyz="0 0 1"/>
<limit effort="1" velocity="20" />
<joint_properties friction="0.0"/>
</joint>

<joint name="thumb_right_opposition" type="revolute">
<origin xyz="0.0098405200000000053739 -0.05700002865907782823 0.0034672156026500644543" rpy="3.1415926535897624738 1.3613568165555642864 -1.5707963267949189845" />
<parent link="urdf_palm_right" />
<child link="urdf_thumb_rotator_right" />
<axis xyz="0 0 1"/>
<limit effort="1" velocity="20" />
<joint_properties friction="0.0"/>
</joint>

<joint name="wrist_right" type="revolute">
<origin xyz="-0.025199999999999972422 -0.014999999999999874545 0.15440000000000020375" rpy="-1.570796326794896336 4.5639825902710352403e-15 1.5707963267948983344" />
<parent link="urdf_forearm_marker" />
<child link="urdf_palm_right" />
<axis xyz="0 0 1"/>
<limit effort="1" velocity="20" />
<joint_properties friction="0.0"/>
</joint>

<link name="sticker_red_3">
<visual>
<origin xyz="0.056831607790372884459 0.042995058148414810884 5.5511151231257827021e-17" rpy="-3.141592653589793116 2.640151083277079582e-17 -5.5511151231257827021e-17" />
<geometry>
<mesh filename="package://pib_cal_sim/meshes/sticker_red.stl"/>
</geometry>
<material name="sticker_red_material">
<color rgba="1 0 0 1.0"/>
</material>
</visual>
<collision>
<origin xyz="0.056831607790372884459 0.042995058148414810884 5.5511151231257827021e-17" rpy="-3.141592653589793116 2.640151083277079582e-17 -5.5511151231257827021e-17" />
<geometry>
<mesh filename="package://pib_cal_sim/meshes/sticker_red.stl"/>
</geometry>
</collision>
<inertial>
<origin xyz="9.7144514654701197287e-17 -1.7661304206520994442e-17 -9.9999999999943057073e-05" rpy="0 0 0"/>
<mass value="1.3079078535425004304e-05" />
<inertia ixx="5.2359911070151346955e-11" ixy="-5.8131178837407631066e-27"  ixz="-1.1673997867047182904e-27" iyy="5.2359911070151327568e-11" iyz="-5.4594247577254580892e-28" izz="1.0463262828339982933e-10" />
</inertial>
</link>

<joint name="connector_red3" type="fixed">
<origin xyz="1.1439294789195031399e-09 0.033600000000000004863 0.12028826000000014673" rpy="-1.570796326794896336 1.570796326794896558 0" />
<parent link="urdf_forearm_marker" />
<child link="sticker_red_3" />
<axis xyz="0 0 1"/>
<limit effort="1" velocity="20" />
<joint_properties friction="0.0"/>
</joint>

<link name="sticker_green_3">
<visual>
<origin xyz="0.041831607790372801747 -0.057995058148414879717 -0.00020000000000000572875" rpy="-5.5511151231257827021e-17 -5.7819424914629794091e-17 -2.2840354735518730089e-17" />
<geometry>
<mesh filename="package://pib_cal_sim/meshes/sticker_green.stl"/>
</geometry>
<material name="sticker_green_material">
<color rgba="0.37254901960784314596 0.65490196078431373028 0.23921568627450981448 1.0"/>
</material>
</visual>
<collision>
<origin xyz="0.041831607790372801747 -0.057995058148414879717 -0.00020000000000000572875" rpy="-5.5511151231257827021e-17 -5.7819424914629794091e-17 -2.2840354735518730089e-17" />
<geometry>
<mesh filename="package://pib_cal_sim/meshes/sticker_green.stl"/>
</geometry>
</collision>
<inertial>
<origin xyz="1.3877787807814456755e-17 -4.7611257451138270047e-17 -0.00010000000000001134826" rpy="0 0 0"/>
<mass value="1.3079078535425004304e-05" />
<inertia ixx="5.2359911070151340492e-11" ixy="-8.7065598471220261086e-28"  ixz="6.5815430353624430016e-27" iyy="5.2359911070151327568e-11" iyz="2.9017187104934117772e-27" izz="1.0463262828339982933e-10" />
</inertial>
</link>

<joint name="connector_green3" type="fixed">
<origin xyz="-0.044703546265191212994 2.7755575615628913511e-17 0.0080000000000001181277" rpy="-1.57079632679489678 4.915220880061267112e-18 1.570796326794896558" />
<parent link="urdf_forearm_marker" />
<child link="sticker_green_3" />
<axis xyz="0 0 1"/>
<limit effort="1" velocity="20" />
<joint_properties friction="0.0"/>
</joint>

<joint name="forearm_right" type="revolute">
<origin xyz="0.020999999999999963141 0.087100000000000066258 -2.7755575615628913511e-17" rpy="-1.57079632679489678 -4.3127257967754209027e-14 1.5543122344752288201e-15" />
<parent link="urdf_ellbow_lower_marker" />
<child link="urdf_forearm_marker" />
<axis xyz="0 0 1"/>
<limit effort="1" velocity="20" />
<joint_properties friction="0.0"/>
</joint>

<link name="sticker_blue_3">
<visual>
<origin xyz="0.056831607790372773437 -0.057995058148414879717 -0.00020000000000003348433" rpy="2.7755575615628907348e-17 1.5771753477875072313e-18 9.7154679050068248891e-18" />
<geometry>
<mesh filename="package://pib_cal_sim/meshes/sticker_blue.stl"/>
</geometry>
<material name="sticker_blue_material">
<color rgba="0 0 1 1.0"/>
</material>
</visual>
<collision>
<origin xyz="0.056831607790372773437 -0.057995058148414879717 -0.00020000000000003348433" rpy="2.7755575615628907348e-17 1.5771753477875072313e-18 9.7154679050068248891e-18" />
<geometry>
<mesh filename="package://pib_cal_sim/meshes/sticker_blue.stl"/>
</geometry>
</collision>
<inertial>
<origin xyz="-1.3877787807814456755e-17 -4.9127178546389465238e-17 -0.00010000000000003174481" rpy="0 0 0"/>
<mass value="1.3079078535425004304e-05" />
<inertia ixx="5.2359911070151346955e-11" ixy="1.3983512902481411709e-27"  ixz="1.5879857704518878922e-26" iyy="5.2359911070151327568e-11" iyz="-1.4508593552467066061e-27" izz="1.0463262828339988103e-10" />
</inertial>
</link>

<joint name="connector_blue3" type="fixed">
<origin xyz="-0.023699538048699481108 0.078899919343884739042 4.5214198635123992176e-09" rpy="-3.1415926533530771358 1.5707812785667194522 -1.9974334782519783131e-05" />
<parent link="urdf_ellbow_lower_marker" />
<child link="sticker_blue_3" />
<axis xyz="0 0 1"/>
<limit effort="1" velocity="20" />
<joint_properties friction="0.0"/>
</joint>

<joint name="ellbow_right" type="revolute">
<origin xyz="-4.1633363423443370266e-17 0.021000000000000018652 0.076337859999999979621" rpy="1.570796326794896558 1.3211653993039277634e-14 -1.57079632679489678" />
<parent link="urdf_ellbow_upper" />
<child link="urdf_ellbow_lower_marker" />
<axis xyz="0 0 1"/>
<limit effort="1" velocity="20" />
<joint_properties friction="0.0"/>
</joint>

<joint name="upper_arm_right" type="revolute">
<origin xyz="-2.7755575615628913511e-17 0.1399999999999999023 -1.3877787807814456755e-17" rpy="-1.570796326794896558 1.5707963267948721331 0" />
<parent link="urdf_shoulder_vertical_marker" />
<child link="urdf_ellbow_upper" />
<axis xyz="0 0 1"/>
<limit effort="1" velocity="20" />
<joint_properties friction="0.0"/>
</joint>

<link name="sticker_purple_3">
<visual>
<origin xyz="0.041831607790372871136 -0.042995058148414866395 -0.00019999999999997797318" rpy="0 -2.2551782824835187317e-17 -4.9375357772016272975e-18" />
<geometry>
<mesh filename="package://pib_cal_sim/meshes/sticker_purple.stl"/>
</geometry>
<material name="sticker_purple_material">
<color rgba="0.59607843137254901134 0.12156862745098039047 0.6745098039215686736 1.0"/>
</material>
</visual>
<collision>
<origin xyz="0.041831607790372871136 -0.042995058148414866395 -0.00019999999999997797318" rpy="0 -2.2551782824835187317e-17 -4.9375357772016272975e-18" />
<geometry>
<mesh filename="package://pib_cal_sim/meshes/sticker_purple.stl"/>
</geometry>
</collision>
<inertial>
<origin xyz="8.3266726846886740532e-17 -4.1421267248237411519e-17 -9.9999999999978930612e-05" rpy="0 0 0"/>
<mass value="1.3079078535425004304e-05" />
<inertia ixx="5.2359911070151346955e-11" ixy="1.097901095561571748e-27"  ixz="-2.2245838867293920601e-26" iyy="5.2359911070151314643e-11" iyz="5.8082776523637922543e-27" izz="1.0463262828339980348e-10" />
</inertial>
</link>

<joint name="connector_purple3" type="fixed">
<origin xyz="-0.044699999999999989742 0.13200000000000011724 0" rpy="-3.141592653589793116 1.570796326794896336 0" />
<parent link="urdf_shoulder_vertical_marker" />
<child link="sticker_purple_3" />
<axis xyz="0 0 1"/>
<limit effort="1" velocity="20" />
<joint_properties friction="0.0"/>
</joint>

<joint name="shoulder_vertical_right" type="revolute">
<origin xyz="4.1633363423443370266e-17 -0.005588974447351582886 0.050000000000000266454" rpy="1.570796326794896558 -0.26179938779916822611 -1.5707963267949001107" />
<parent link="urdf_shoulder_horizontal" />
<child link="urdf_shoulder_vertical_marker" />
<axis xyz="0 0 1"/>
<limit effort="1" velocity="20" />
<joint_properties friction="0.0"/>
</joint>

<joint name="shoulder_horizontal_right" type="revolute">
<origin xyz="0.12963280242320607272 -0.0039402433919477983931 1.1336467136047998494" rpy="-3.1415926535897908956 4.7522392547319886719e-15 -0.78539816339744683571" />
<parent link="urdf_body" />
<child link="urdf_shoulder_horizontal" />
<axis xyz="0 0 1"/>
<limit effort="1" velocity="20" />
<joint_properties friction="0.0"/>
</joint>

<link name="urdf_shoulder_horizontal_2">
<visual>
<origin xyz="0 5.5511151231257827021e-17 -0.0081999999999999850786" rpy="-3.141592653589793116 -1.232595164407830946e-32 -1.3031514307600699517e-33" />
<geometry>
<mesh filename="package://pib_cal_sim/meshes/urdf_shoulder_horizontal.stl"/>
</geometry>
<material name="urdf_shoulder_horizontal_material">
<color rgba="0.90196078431372550543 0.90196078431372550543 0.90196078431372550543 1.0"/>
</material>
</visual>
<collision>
<origin xyz="0 5.5511151231257827021e-17 -0.0081999999999999850786" rpy="-3.141592653589793116 -1.232595164407830946e-32 -1.3031514307600699517e-33" />
<geometry>
<mesh filename="package://pib_cal_sim/meshes/urdf_shoulder_horizontal.stl"/>
</geometry>
</collision>
<inertial>
<origin xyz="0.00014552549411057637491 -0.0019932645268490828232 0.021127140613376407807" rpy="0 0 0"/>
<mass value="0.37235551761859836395" />
<inertia ixx="0.00069298290097298304198" ixy="-4.4552008487092734506e-07"  ixz="1.4458402066394983752e-06" iyy="0.00063232764424174547381" iyz="5.0607205205189875015e-05" izz="0.00072108918939828054069" />
</inertial>
</link>

<link name="urdf_shoulder_vertical">
<visual>
<origin xyz="-1.1102230246251565404e-16 -0.05820000000000014051 -5.5511151231257827021e-17" rpy="1.570796326794896558 1.570796326794896336 0" />
<geometry>
<mesh filename="package://pib_cal_sim/meshes/urdf_shoulder_vertical.stl"/>
</geometry>
<material name="urdf_shoulder_vertical_material">
<color rgba="0.90196078431372550543 0.90196078431372550543 0.90196078431372550543 1.0"/>
</material>
</visual>
<collision>
<origin xyz="-1.1102230246251565404e-16 -0.05820000000000014051 -5.5511151231257827021e-17" rpy="1.570796326794896558 1.570796326794896336 0" />
<geometry>
<mesh filename="package://pib_cal_sim/meshes/urdf_shoulder_vertical.stl"/>
</geometry>
</collision>
<inertial>
<origin xyz="0.011606085871020353426 0.048247879791954662032 -4.0119040967249975294e-07" rpy="0 0 0"/>
<mass value="0.43439604991767988285" />
<inertia ixx="0.001143124372344151091" ixy="1.8159661577359596639e-05"  ixz="-1.2483130103650728669e-08" iyy="0.00062872884803634530426" iyz="-6.1959044597032014876e-09" izz="0.00081534982463337291481" />
</inertial>
</link>

<link name="urdf_ellbow_upper_2">
<visual>
<origin xyz="1.6653345369377348106e-16 1.1102230246251565404e-16 0.076337859999999979621" rpy="-3.141592653589793116 1.1348979659686652708e-17 -3.0692907694036966976e-17" />
<geometry>
<mesh filename="package://pib_cal_sim/meshes/urdf_ellbow_upper.stl"/>
</geometry>
<material name="urdf_ellbow_upper_material">
<color rgba="0.90196078431372550543 0.90196078431372550543 0.90196078431372550543 1.0"/>
</material>
</visual>
<collision>
<origin xyz="1.6653345369377348106e-16 1.1102230246251565404e-16 0.076337859999999979621" rpy="-3.141592653589793116 1.1348979659686652708e-17 -3.0692907694036966976e-17" />
<geometry>
<mesh filename="package://pib_cal_sim/meshes/urdf_ellbow_upper.stl"/>
</geometry>
</collision>
<inertial>
<origin xyz="-8.7828098901160576669e-05 0.0054300548508615809756 0.022553116578299087225" rpy="0 0 0"/>
<mass value="0.18102575322750719122" />
<inertia ixx="0.00016816998365107977374" ixy="-5.2718247233669830333e-07"  ixz="-2.0631507098792030199e-07" iyy="0.00028060174234195706241" iyz="-2.5081698616751792549e-05" izz="0.00027446559514037295949" />
</inertial>
</link>

<link name="urdf_ellbow_lower">
<visual>
<origin xyz="0.021000000000000018652 1.1102230246251565404e-16 5.5511151231257827021e-17" rpy="1.570796326794896558 1.570796326794896558 0" />
<geometry>
<mesh filename="package://pib_cal_sim/meshes/urdf_ellbow_lower.stl"/>
</geometry>
<material name="urdf_ellbow_lower_material">
<color rgba="0.90196078431372550543 0.90196078431372550543 0.90196078431372550543 1.0"/>
</material>
</visual>
<collision>
<origin xyz="0.021000000000000018652 1.1102230246251565404e-16 5.5511151231257827021e-17" rpy="1.570796326794896558 1.570796326794896558 0" />
<geometry>
<mesh filename="package://pib_cal_sim/meshes/urdf_ellbow_lower.stl"/>
</geometry>
</collision>
<inertial>
<origin xyz="0.020545274391323264246 0.040793215391606435505 0.0010180423805795587883" rpy="0 0 0"/>
<mass value="0.20654790993195132343" />
<inertia ixx="0.00033807391539849885069" ixy="-3.8668826604869293163e-05"  ixz="8.9148530890997817056e-06" iyy="0.00034895445555060288943" iyz="3.475070463491772599e-06" izz="0.0002684459486497316541" />
</inertial>
</link>

<link name="urdf_forearm_marker_2">
<visual>
<origin xyz="0.057963134702951002453 1.1102230246251565404e-16 0.14991149095677980263" rpy="-3.141592653589793116 -0 1.3279518363332706561e-17" />
<geometry>
<mesh filename="package://pib_cal_sim/meshes/urdf_forearm_marker.stl"/>
</geometry>
<material name="urdf_forearm_marker_material">
<color rgba="0.90196078431372550543 0.90196078431372550543 0.90196078431372550543 1.0"/>
</material>
</visual>
<collision>
<origin xyz="0.057963134702951002453 1.1102230246251565404e-16 0.14991149095677980263" rpy="-3.141592653589793116 -0 1.3279518363332706561e-17" />
<geometry>
<mesh filename="package://pib_cal_sim/meshes/urdf_forearm_marker.stl"/>
</geometry>
</collision>
<inertial>
<origin xyz="7.6595342837354474241e-06 -0.0012073011042543478101 0.05206804160617312105" rpy="0 0 0"/>
<mass value="0.055999999999999952593" />
<inertia ixx="0.00016791550498575073293" ixy="-6.9647662096350307517e-10"  ixz="1.5058530731286386468e-08" iyy="0.00017557241384765498991" iyz="2.2983836036069374465e-06" izz="7.0754380195781182896e-05" />
</inertial>
</link>

<link name="urdf_palm_left">
<visual>
<origin xyz="0.0029999999999997806199 0.099999999999999922284 -0.017699999999999938005" rpy="-1.57079632679489678 -1.5707963267948961139 0" />
<geometry>
<mesh filename="package://pib_cal_sim/meshes/urdf_palm_left.stl"/>
</geometry>
<material name="urdf_palm_left_material">
<color rgba="0.90196078431372550543 0.90196078431372550543 0.90196078431372550543 1.0"/>
</material>
</visual>
<collision>
<origin xyz="0.0029999999999997806199 0.099999999999999922284 -0.017699999999999938005" rpy="-1.57079632679489678 -1.5707963267948961139 0" />
<geometry>
<mesh filename="package://pib_cal_sim/meshes/urdf_palm_left.stl"/>
</geometry>
</collision>
<inertial>
<origin xyz="0.0013063193807914838616 0.046622993734774860475 -0.027814259162596721708" rpy="0 0 0"/>
<mass value="0.17357701466710764859" />
<inertia ixx="0.00019639131041877613023" ixy="-4.5609933520240672337e-06"  ixz="2.3506111612140208e-06" iyy="7.6814643537185820833e-05" iyz="-7.8583554601542360317e-06" izz="0.00013865885062512600017" />
</inertial>
</link>

<link name="urdf_finger_proximal_2">
<visual>
<origin xyz="0 0 0" rpy="1.570796326794896558 1.570796326794896558 0" />
<geometry>
<mesh filename="package://pib_cal_sim/meshes/urdf_finger_proximal.stl"/>
</geometry>
<material name="urdf_finger_proximal_material">
<color rgba="0.90196078431372550543 0.90196078431372550543 0.90196078431372550543 1.0"/>
</material>
</visual>
<collision>
<origin xyz="0 0 0" rpy="1.570796326794896558 1.570796326794896558 0" />
<geometry>
<mesh filename="package://pib_cal_sim/meshes/urdf_finger_proximal.stl"/>
</geometry>
</collision>
<inertial>
<origin xyz="0.0017705852400310762625 -0.023999099540417963283 2.3033977339243641501e-05" rpy="0 0 0"/>
<mass value="0.013487983354878252049" />
<inertia ixx="2.4205995838425492106e-06" ixy="3.067842829119936923e-10"  ixz="-1.3933704801258381444e-09" iyy="7.1089856531410673884e-07" iyz="-5.2774001918341979554e-09" izz="2.3870217482857892183e-06" />
</inertial>
</link>

<link name="urdf_finger_distal_2">
<visual>
<origin xyz="-5.5511151231257827021e-17 0.048000000000000042633 0" rpy="1.570796326794896558 1.570796326794896558 0" />
<geometry>
<mesh filename="package://pib_cal_sim/meshes/urdf_finger_distal.stl"/>
</geometry>
<material name="urdf_finger_distal_material">
<color rgba="0.90196078431372550543 0.90196078431372550543 0.90196078431372550543 1.0"/>
</material>
</visual>
<collision>
<origin xyz="-5.5511151231257827021e-17 0.048000000000000042633 0" rpy="1.570796326794896558 1.570796326794896558 0" />
<geometry>
<mesh filename="package://pib_cal_sim/meshes/urdf_finger_distal.stl"/>
</geometry>
</collision>
<inertial>
<origin xyz="0.0040511578091626098547 -0.025115354711068127447 8.7468318802999329607e-06" rpy="0 0 0"/>
<mass value="0.015970996140918996414" />
<inertia ixx="2.897551169824546136e-06" ixy="4.0367178625229530908e-07"  ixz="5.572585289384433068e-10" iyy="9.5795739134608018753e-07" iyz="-1.2993500709766039319e-09" izz="2.8722130952212174432e-06" />
</inertial>
</link>

<joint name="pinky_left_distal" type="revolute">
<origin xyz="5.5511151231257827021e-17 -0.047999999999999820588 5.5511151231257827021e-17" rpy="6.9388939039072376221e-18 1.8817924898548425933e-15 4.6565597964452575849e-16" />
<parent link="urdf_finger_proximal_2" />
<child link="urdf_finger_distal_2" />
<axis xyz="0 0 1"/>
<limit effort="1" velocity="20" />
<joint_properties friction="0.0"/>
</joint>

<joint name="pinky_left_proximal" type="revolute">
<origin xyz="0.0029999999999997251088 0.075546139999999983861 -0.065820550000000088708" rpy="2.8274333882308142485 8.0529940592273967177e-16 7.6732355047702474587e-16" />
<parent link="urdf_palm_left" />
<child link="urdf_finger_proximal_2" />
<axis xyz="0 0 1"/>
<limit effort="1" velocity="20" />
<joint_properties friction="0.0"/>
</joint>

<link name="urdf_finger_proximal_3">
<visual>
<origin xyz="5.5511151231257827021e-17 0 1.1102230246251565404e-16" rpy="1.570796326794896558 1.570796326794896558 0" />
<geometry>
<mesh filename="package://pib_cal_sim/meshes/urdf_finger_proximal.stl"/>
</geometry>
<material name="urdf_finger_proximal_material">
<color rgba="0.90196078431372550543 0.90196078431372550543 0.90196078431372550543 1.0"/>
</material>
</visual>
<collision>
<origin xyz="5.5511151231257827021e-17 0 1.1102230246251565404e-16" rpy="1.570796326794896558 1.570796326794896558 0" />
<geometry>
<mesh filename="package://pib_cal_sim/meshes/urdf_finger_proximal.stl"/>
</geometry>
</collision>
<inertial>
<origin xyz="0.0017705852400311319905 -0.023999099540417959814 2.3033977339354314826e-05" rpy="0 0 0"/>
<mass value="0.013487983354878252049" />
<inertia ixx="2.4205995838425492106e-06" ixy="3.0678428291198531709e-10"  ixz="-1.3933704801258178784e-09" iyy="7.1089856531410652708e-07" iyz="-5.2774001918341375713e-09" izz="2.3870217482857892183e-06" />
</inertial>
</link>

<link name="urdf_finger_distal_3">
<visual>
<origin xyz="-1.1102230246251565404e-16 0.04799999999999993161 0" rpy="1.570796326794896558 1.570796326794896558 0" />
<geometry>
<mesh filename="package://pib_cal_sim/meshes/urdf_finger_distal.stl"/>
</geometry>
<material name="urdf_finger_distal_material">
<color rgba="0.90196078431372550543 0.90196078431372550543 0.90196078431372550543 1.0"/>
</material>
</visual>
<collision>
<origin xyz="-1.1102230246251565404e-16 0.04799999999999993161 0" rpy="1.570796326794896558 1.570796326794896558 0" />
<geometry>
<mesh filename="package://pib_cal_sim/meshes/urdf_finger_distal.stl"/>
</geometry>
</collision>
<inertial>
<origin xyz="0.0040511578091625552109 -0.025115354711068252347 8.7468318802992248411e-06" rpy="0 0 0"/>
<mass value="0.015970996140918996414" />
<inertia ixx="2.8975511698245469831e-06" ixy="4.036717862522954679e-07"  ixz="5.57258528938605641e-10" iyy="9.5795739134608061105e-07" iyz="-1.2993500709765210071e-09" izz="2.8722130952212191373e-06" />
</inertial>
</link>

<joint name="ring_left_distal" type="revolute">
<origin xyz="1.1102230246251565404e-16 -0.048000000000000042633 1.1102230246251565404e-16" rpy="6.6613381477509560058e-16 -1.4683501479060618711e-15 2.0597046351991948482e-16" />
<parent link="urdf_finger_proximal_3" />
<child link="urdf_finger_distal_3" />
<axis xyz="0 0 1"/>
<limit effort="1" velocity="20" />
<joint_properties friction="0.0"/>
</joint>

<joint name="ring_left_proximal" type="revolute">
<origin xyz="0.0029999999999997251088 0.088617510000000010439 -0.043501980000000051163" rpy="2.9670597283903576979 -2.442362632043816757e-15 1.2882659839987202116e-15" />
<parent link="urdf_palm_left" />
<child link="urdf_finger_proximal_3" />
<axis xyz="0 0 1"/>
<limit effort="1" velocity="20" />
<joint_properties friction="0.0"/>
</joint>

<link name="urdf_finger_proximal_4">
<visual>
<origin xyz="1.1102230246251565404e-16 -5.5511151231257827021e-17 -1.1102230246251565404e-16" rpy="1.570796326794896558 1.570796326794896558 0" />
<geometry>
<mesh filename="package://pib_cal_sim/meshes/urdf_finger_proximal.stl"/>
</geometry>
<material name="urdf_finger_proximal_material">
<color rgba="0.90196078431372550543 0.90196078431372550543 0.90196078431372550543 1.0"/>
</material>
</visual>
<collision>
<origin xyz="1.1102230246251565404e-16 -5.5511151231257827021e-17 -1.1102230246251565404e-16" rpy="1.570796326794896558 1.570796326794896558 0" />
<geometry>
<mesh filename="package://pib_cal_sim/meshes/urdf_finger_proximal.stl"/>
</geometry>
</collision>
<inertial>
<origin xyz="0.0017705852400311868512 -0.023999099540418018794 2.3033977339133947346e-05" rpy="0 0 0"/>
<mass value="0.013487983354878252049" />
<inertia ixx="2.4205995838425492106e-06" ixy="3.0678428291199276172e-10"  ixz="-1.3933704801257787942e-09" iyy="7.1089856531410673884e-07" iyz="-5.277400191834287291e-09" izz="2.3870217482857892183e-06" />
</inertial>
</link>

<link name="urdf_finger_distal_4">
<visual>
<origin xyz="0 0.047999999999999987121 0" rpy="1.570796326794896558 1.570796326794896558 0" />
<geometry>
<mesh filename="package://pib_cal_sim/meshes/urdf_finger_distal.stl"/>
</geometry>
<material name="urdf_finger_distal_material">
<color rgba="0.90196078431372550543 0.90196078431372550543 0.90196078431372550543 1.0"/>
</material>
</visual>
<collision>
<origin xyz="0 0.047999999999999987121 0" rpy="1.570796326794896558 1.570796326794896558 0" />
<geometry>
<mesh filename="package://pib_cal_sim/meshes/urdf_finger_distal.stl"/>
</geometry>
</collision>
<inertial>
<origin xyz="0.0040511578091626644985 -0.025115354711068196836 8.7468318802988436763e-06" rpy="0 0 0"/>
<mass value="0.015970996140918996414" />
<inertia ixx="2.8975511698245469831e-06" ixy="4.0367178625229552084e-07"  ixz="5.572585289386395554e-10" iyy="9.5795739134608061105e-07" iyz="-1.299350070976439323e-09" izz="2.8722130952212191373e-06" />
</inertial>
</link>

<joint name="middle_left_distal" type="revolute">
<origin xyz="2.2204460492503130808e-16 -0.048000000000000153655 0" rpy="7.2164496600635263874e-16 -4.7050204075983547898e-15 -6.5963826391124250154e-17" />
<parent link="urdf_finger_proximal_4" />
<child link="urdf_finger_distal_4" />
<axis xyz="0 0 1"/>
<limit effort="1" velocity="20" />
<joint_properties friction="0.0"/>
</joint>

<joint name="middle_left_proximal" type="revolute">
<origin xyz="0.0029999999999997806199 0.099999999999999922284 -0.017699999999999938005" rpy="3.1415926535897900074 -4.1789449501852165692e-15 1.7013808668675476216e-15" />
<parent link="urdf_palm_left" />
<child link="urdf_finger_proximal_4" />
<axis xyz="0 0 1"/>
<limit effort="1" velocity="20" />
<joint_properties friction="0.0"/>
</joint>

<link name="urdf_finger_proximal_5">
<visual>
<origin xyz="-2.7755575615628913511e-16 5.5511151231257827021e-17 2.2204460492503130808e-16" rpy="1.570796326794896558 1.570796326794896558 0" />
<geometry>
<mesh filename="package://pib_cal_sim/meshes/urdf_finger_proximal.stl"/>
</geometry>
<material name="urdf_finger_proximal_material">
<color rgba="0.90196078431372550543 0.90196078431372550543 0.90196078431372550543 1.0"/>
</material>
</visual>
<collision>
<origin xyz="-2.7755575615628913511e-16 5.5511151231257827021e-17 2.2204460492503130808e-16" rpy="1.570796326794896558 1.570796326794896558 0" />
<geometry>
<mesh filename="package://pib_cal_sim/meshes/urdf_finger_proximal.stl"/>
</geometry>
</collision>
<inertial>
<origin xyz="0.0017705852400307976226 -0.023999099540417907772 2.303397733946707524e-05" rpy="0 0 0"/>
<mass value="0.013487983354878252049" />
<inertia ixx="2.4205995838425492106e-06" ixy="3.0678428291205386968e-10"  ixz="-1.3933704801253987047e-09" iyy="7.1089856531410673884e-07" iyz="-5.2774001918342211165e-09" izz="2.3870217482857892183e-06" />
</inertial>
</link>

<link name="urdf_finger_distal_5">
<visual>
<origin xyz="0 0.048000000000000070388 0" rpy="1.570796326794896558 1.570796326794896558 0" />
<geometry>
<mesh filename="package://pib_cal_sim/meshes/urdf_finger_distal.stl"/>
</geometry>
<material name="urdf_finger_distal_material">
<color rgba="0.90196078431372550543 0.90196078431372550543 0.90196078431372550543 1.0"/>
</material>
</visual>
<collision>
<origin xyz="0 0.048000000000000070388 0" rpy="1.570796326794896558 1.570796326794896558 0" />
<geometry>
<mesh filename="package://pib_cal_sim/meshes/urdf_finger_distal.stl"/>
</geometry>
</collision>
<inertial>
<origin xyz="0.0040511578091626679679 -0.025115354711068113569 8.7468318802948084113e-06" rpy="0 0 0"/>
<mass value="0.015970996140918996414" />
<inertia ixx="2.8975511698245469831e-06" ixy="4.036717862522954679e-07"  ixz="5.5725852893857751686e-10" iyy="9.5795739134608061105e-07" iyz="-1.2993500709763834883e-09" izz="2.8722130952212174432e-06" />
</inertial>
</link>

<joint name="index_left_distal" type="revolute">
<origin xyz="-2.2204460492503130808e-16 -0.047999999999999987121 2.2204460492503130808e-16" rpy="1.6653345369377367828e-16 -4.3687039353566093571e-16 8.7108723709687750807e-16" />
<parent link="urdf_finger_proximal_5" />
<child link="urdf_finger_distal_5" />
<axis xyz="0 0 1"/>
<limit effort="1" velocity="20" />
<joint_properties friction="0.0"/>
</joint>

<joint name="index_left_proximal" type="revolute">
<origin xyz="0.0029999999999997251088 0.088617510000000065951 0.0081019799999999531082" rpy="-2.9670597283903656916 -2.0641407275565273248e-15 2.6998093480807669939e-15" />
<parent link="urdf_palm_left" />
<child link="urdf_finger_proximal_5" />
<axis xyz="0 0 1"/>
<limit effort="1" velocity="20" />
<joint_properties friction="0.0"/>
</joint>

<link name="urdf_thumb_rotator_left">
<visual>
<origin xyz="-0.029644857902553445328 -0.0068405200000001276095 0.037909407212894152828" rpy="1.1642056880864825608e-16 -0.2094395102393194763 -3.7572313173899314223e-17" />
<geometry>
<mesh filename="package://pib_cal_sim/meshes/urdf_thumb_rotator_left.stl"/>
</geometry>
<material name="urdf_thumb_rotator_left_material">
<color rgba="0.90196078431372550543 0.90196078431372550543 0.90196078431372550543 1.0"/>
</material>
</visual>
<collision>
<origin xyz="-0.029644857902553445328 -0.0068405200000001276095 0.037909407212894152828" rpy="1.1642056880864825608e-16 -0.2094395102393194763 -3.7572313173899314223e-17" />
<geometry>
<mesh filename="package://pib_cal_sim/meshes/urdf_thumb_rotator_left.stl"/>
</geometry>
</collision>
<inertial>
<origin xyz="0.0029570727731400708871 -0.0010046866255538011107 -0.025659714176101092176" rpy="0 0 0"/>
<mass value="0.016982049144740864188" />
<inertia ixx="2.0820566619870095438e-06" ixy="1.3198814179763775674e-07"  ixz="2.8002957154581382263e-07" iyy="2.5044471968613933344e-06" iyz="-4.2387894588249593279e-08" izz="1.6386414948788689262e-06" />
</inertial>
</link>

<link name="urdf_finger_proximal_6">
<visual>
<origin xyz="-5.5511151231257827021e-17 -1.1102230246251565404e-16 2.7755575615628913511e-17" rpy="1.570796326794896558 1.570796326794896558 0" />
<geometry>
<mesh filename="package://pib_cal_sim/meshes/urdf_finger_proximal.stl"/>
</geometry>
<material name="urdf_finger_proximal_material">
<color rgba="0.90196078431372550543 0.90196078431372550543 0.90196078431372550543 1.0"/>
</material>
</visual>
<collision>
<origin xyz="-5.5511151231257827021e-17 -1.1102230246251565404e-16 2.7755575615628913511e-17" rpy="1.570796326794896558 1.570796326794896558 0" />
<geometry>
<mesh filename="package://pib_cal_sim/meshes/urdf_finger_proximal.stl"/>
</geometry>
</collision>
<inertial>
<origin xyz="0.0017705852400310207514 -0.023999099540418074306 2.3033977339272748941e-05" rpy="0 0 0"/>
<mass value="0.013487983354878252049" />
<inertia ixx="2.4205995838425492106e-06" ixy="3.0678428291213224505e-10"  ixz="-1.393370480125691113e-09" iyy="7.1089856531410673884e-07" iyz="-5.2774001918340879404e-09" izz="2.3870217482857883713e-06" />
</inertial>
</link>

<link name="urdf_finger_distal_6">
<visual>
<origin xyz="0 0.048000000000000042633 0" rpy="1.570796326794896558 1.570796326794896558 0" />
<geometry>
<mesh filename="package://pib_cal_sim/meshes/urdf_finger_distal.stl"/>
</geometry>
<material name="urdf_finger_distal_material">
<color rgba="0.90196078431372550543 0.90196078431372550543 0.90196078431372550543 1.0"/>
</material>
</visual>
<collision>
<origin xyz="0 0.048000000000000042633 0" rpy="1.570796326794896558 1.570796326794896558 0" />
<geometry>
<mesh filename="package://pib_cal_sim/meshes/urdf_finger_distal.stl"/>
</geometry>
</collision>
<inertial>
<origin xyz="0.004051157809162661029 -0.025115354711068141325 8.7468318802968667014e-06" rpy="0 0 0"/>
<mass value="0.015970996140918996414" />
<inertia ixx="2.8975511698245469831e-06" ixy="4.0367178625229567966e-07"  ixz="5.5725852893873530156e-10" iyy="9.5795739134608061105e-07" iyz="-1.2993500709766461181e-09" izz="2.8722130952212174432e-06" />
</inertial>
</link>

<joint name="thumb_left_distal" type="revolute">
<origin xyz="-1.6653345369377348106e-16 -0.048000000000000264677 -8.3266726846886740532e-17" rpy="-5.5511151231257827021e-17 -0 -3.8691272408186705434e-14" />
<parent link="urdf_finger_proximal_6" />
<child link="urdf_finger_distal_6" />
<axis xyz="0 0 1"/>
<limit effort="1" velocity="20" />
<joint_properties friction="0.0"/>
</joint>

<joint name="thumb_left_proximal" type="revolute">
<origin xyz="0.020000000000000239808 -0.001320260000000128553 -0.029914960629476461396" rpy="-7.815970093360920291e-14 -1.047197551196551224 1.5707963267950142416" />
<parent link="urdf_thumb_rotator_left" />
<child link="urdf_finger_proximal_6" />
<axis xyz="0 0 1"/>
<limit effort="1" velocity="20" />
<joint_properties friction="0.0"/>
</joint>

<joint name="thumb_left_opposition" type="revolute">
<origin xyz="0.0098405199999997972071 0.057000028659077883741 0.0034672156026500644543" rpy="1.1973237632944844534e-13 -1.3613568165555891554 -1.5707963267948494845" />
<parent link="urdf_palm_left" />
<child link="urdf_thumb_rotator_left" />
<axis xyz="0 0 1"/>
<limit effort="1" velocity="20" />
<joint_properties friction="0.0"/>
</joint>

<joint name="wrist_left" type="revolute">
<origin xyz="0.025199999999999778133 -0.014999999999999680256 0.15440000000000003721" rpy="1.5707963267948970021 -1.9705423371320408019e-15 1.5707963267948961139" />
<parent link="urdf_forearm_marker_2" />
<child link="urdf_palm_left" />
<axis xyz="0 0 1"/>
<limit effort="1" velocity="20" />
<joint_properties friction="0.0"/>
</joint>

<joint name="forearm_left" type="revolute">
<origin xyz="0.021000000000000129674 0.087100000000000066258 -5.5511151231257827021e-17" rpy="1.57079632679489678 2.4000607722530672619e-15 -3.1415926535897908956" />
<parent link="urdf_ellbow_lower" />
<child link="urdf_forearm_marker_2" />
<axis xyz="0 0 1"/>
<limit effort="1" velocity="20" />
<joint_properties friction="0.0"/>
</joint>

<joint name="ellbow_left" type="revolute">
<origin xyz="1.6653345369377348106e-16 0.021000000000000018652 0.076337860000000090643" rpy="1.570796326794896558 -5.5511151231257260027e-17 -1.5707963267948881203" />
<parent link="urdf_ellbow_upper_2" />
<child link="urdf_ellbow_lower" />
<axis xyz="0 0 1"/>
<limit effort="1" velocity="20" />
<joint_properties friction="0.0"/>
</joint>

<joint name="upper_arm_left" type="revolute">
<origin xyz="-2.2204460492503130808e-16 0.13999999999999934719 3.3306690738754696213e-16" rpy="-1.570796326794896558 1.570796326794896336 0" />
<parent link="urdf_shoulder_vertical" />
<child link="urdf_ellbow_upper_2" />
<axis xyz="0 0 1"/>
<limit effort="1" velocity="20" />
<joint_properties friction="0.0"/>
</joint>

<joint name="shoulder_vertical_left" type="revolute">
<origin xyz="2.7755575615628913511e-16 -2.2204460492503130808e-16 0.050000000000000266454" rpy="1.57079632679489678 -0.26179938779914940783 -1.57079632679489678" />
<parent link="urdf_shoulder_horizontal_2" />
<child link="urdf_shoulder_vertical" />
<axis xyz="0 0 1"/>
<limit effort="1" velocity="20" />
<joint_properties friction="0.0"/>
</joint>

<joint name="shoulder_horizontal_left" type="revolute">
<origin xyz="0.50141994284637769752 -0.0039402433919478859967 1.1336467136047998494" rpy="-3.141592653589793116 -6.6398710397094622971e-17 0.785398163397448279" />
<parent link="urdf_body" />
<child link="urdf_shoulder_horizontal_2" />
<axis xyz="0 0 1"/>
<limit effort="1" velocity="20" />
<joint_properties friction="0.0"/>
</joint>


</robot>
